<?xml version="1.0" ?>
<robot name="balancing_robot">
  <link name="frame">
    <inertial>
      <origin xyz="-0.00825969 0.0374379 0.0410191" rpy="0 0 0"/>
      <mass value="0.617"/>
      <inertia ixx="0.00271437" ixy="1.40011e-08" ixz="8.83996e-06" iyy="0.0050345" iyz="2.25796e-10" izz="0.00261345"/>
    </inertial>

    <visual>
      <origin xyz="-0.018 0.038 -0.0899831" rpy="3.14159 0 3.14159"/>
      <geometry>
        <mesh filename="./assets/robot_stablizujacy_silnik.stl"/>
      </geometry>
      <material name="robot_stablizujacy_silnik_material">
        <color rgba="0.768627 0.886275 0.952941 1"/>
      </material>
    </visual>
    <collision>
      <origin xyz="-0.018 0.038 -0.0899831" rpy="3.14159 0 3.14159"/>
      <geometry>
        <mesh filename="./assets/robot_stablizujacy_silnik.stl"/>
      </geometry>
    </collision>

    <visual>
      <origin xyz="-0.0784829 0.0748364 0.0850084" rpy="0 0 0"/>
      <geometry>
        <mesh filename="./assets/lipo.stl"/>
      </geometry>
      <material name="lipo_material">
        <color rgba="0.615686 0.811765 0.929412 1"/>
      </material>
    </visual>
    <collision>
      <origin xyz="-0.0784829 0.0748364 0.0850084" rpy="0 0 0"/>
      <geometry>
        <mesh filename="./assets/lipo.stl"/>
      </geometry>
    </collision>

    <visual>
      <origin xyz="0.002 0.038 0" rpy="0 0 0"/>
      <geometry>
        <mesh filename="./assets/robot_stablizujacy_silnik.stl"/>
      </geometry>
      <material name="robot_stablizujacy_silnik_2_material">
        <color rgba="0.768627 0.886275 0.952941 1"/>
      </material>
    </visual>
    <collision>
      <origin xyz="0.002 0.038 0" rpy="0 0 0"/>
      <geometry>
        <mesh filename="./assets/robot_stablizujacy_silnik.stl"/>
      </geometry>
    </collision>

    <visual>
      <origin xyz="0.002 0.038 0" rpy="0 0 0"/>
      <geometry>
        <mesh filename="./assets/robot_stabilizujacy_rama.stl"/>
      </geometry>
      <material name="robot_stabilizujacy_rama_material">
        <color rgba="0.980392 0.713725 0.00392157 1"/>
      </material>
    </visual>
    <collision>
      <origin xyz="0.002 0.038 0" rpy="0 0 0"/>
      <geometry>
        <mesh filename="./assets/robot_stabilizujacy_rama.stl"/>
      </geometry>
    </collision>
  </link>

  <link name="wheel">
    <inertial>
      <origin xyz="0 0 0.00154919" rpy="0 0 0"/>
      <mass value="0.03"/>
      <inertia ixx="2.08867e-05" ixy="0" ixz="0" iyy="2.08867e-05" iyz="0" izz="4.17237e-05"/>
    </inertial>
    <visual>
      <origin xyz="0.000562153 -0.0449916 -0.1078" rpy="1.5708 1.5708 0"/>
      <geometry>
        <mesh filename="./assets/wheel.stl"/>
      </geometry>
      <material name="wheel_material">
        <color rgba="0.301961 0.301961 0.301961 1"/>
      </material>
    </visual>
    <collision>
      <origin xyz="0.000562153 -0.0449916 -0.1078" rpy="1.5708 1.5708 0"/>
      <geometry>
        <mesh filename="./assets/wheel.stl"/>
      </geometry>
    </collision>
  </link>

  <joint name="frame_to_wheel_1" type="continuous">
    <origin xyz="0.0898 0.0374378 -0.0449916" rpy="1.5708 0 1.5708"/>
    <parent link="frame"/>
    <child link="wheel"/>
    <axis xyz="0 0 1"/>
    <limit effort="1.0" velocity="50"/> 
    <dynamics damping="0.01" friction="0.02"/>
  </joint>

  <link name="wheel_2">
    <inertial>
      <origin xyz="0 0 0.00154919" rpy="0 0 0"/>
      <mass value="0.03"/>
      <inertia ixx="2.08867e-05" ixy="0" ixz="0" iyy="2.08867e-05" iyz="0" izz="4.17237e-05"/>
    </inertial>
    <visual>
      <origin xyz="0.000562153 -0.0449916 -0.1078" rpy="1.5708 1.5708 0"/>
      <geometry>
        <mesh filename="./assets/wheel.stl"/>
      </geometry>
      <material name="wheel_2_material">
        <color rgba="0.301961 0.301961 0.301961 1"/>
      </material>
    </visual>
    <collision>
      <origin xyz="0.000562153 -0.0449916 -0.1078" rpy="1.5708 1.5708 0"/>
      <geometry>
        <mesh filename="./assets/wheel.stl"/>
      </geometry>
    </collision>
  </link>

  <joint name="frame_to_wheel_2" type="continuous">
    <origin xyz="-0.1058 0.0374378 -0.0449916" rpy="-1.5708 0 1.5708"/>
    <parent link="frame"/>
    <child link="wheel_2"/>
    <axis xyz="0 0 1"/>
    <limit effort="1.0" velocity="50"/> 
    <dynamics damping="0.01" friction="0.02"/>
  </joint>
</robot>